<mujoco model="cartpole">
  <option iterations="50" timestep="0.001" solver="PGS" gravity="0 0 -9.81" />

  <compiler angle="radian" meshdir="meshes" eulerseq="zyx" autolimits="true" />

  <default>
    <joint limited="true" damping="0.01" armature="0.01" frictionloss="0.01" />
    <geom condim="4" contype="1" conaffinity="15" friction="0.9 0.2 0.2" solref="0.001 2" />
    <motor ctrllimited="true" />
    <equality solref="0.001 2" />
    <default class="visualgeom">
      <geom material="visualgeom" condim="1" contype="0" conaffinity="0" />
    </default>
  </default>

  <worldbody>
    <!-- 显示默认地面 -->
    <geom name="ground" type="plane" pos="0 0 0" size="100 100 0.001" quat="1 0 0 0" material="matplane" condim="3" conaffinity="15" rgba="0 0 0 1" />
    
    <light directional="true" diffuse="0.4 0.4 0.4" specular="0.1 0.1 0.1" pos="0 0 5.0" dir="0 0 -1" castshadow="false" />
    <light directional="true" diffuse="0.6 0.6 0.6" specular="0.2 0.2 0.2" pos="0 0 4" dir="0 0 -1" />
    <camera name="fixed" pos="0 -3.0 0.6" xyaxes="1 0 0 0 0 1" />
    <camera name="track" mode="trackcom" pos="0 -3.0 0.6" xyaxes="1 0 0 0 0 1" />
    
    <!-- 提高整个装置的初始高度 -->
    <body name="root" pos="0 0 0.2" quat="1 0 0 0">
      <!-- 添加 inertial -->
      <inertial pos="0 0 0" mass="1" diaginertia="0.01 0.01 0.01"/>
      <freejoint name="root" />
      <site name="imu" size="0.01" pos="0 0 0" />
      
      <!-- 固定 slider -->
      <body name="slider" pos="0 0 0.2">
        <geom size="0.015 4 0.015" type="box" rgba="0.9 0.6 0.2 1" contype="1" conaffinity="0" density="0" group="1" class="visualgeom" />
      </body>
      
      <!-- cart 在 slider 上滑动 -->
      <body name="cart" pos="0 0 0.2">
        <inertial pos="0 0 0" mass="1" diaginertia="0.002 0.002 0.002" />
        <joint name="slider_to_cart" pos="0 0 0" axis="0 1 0" type="slide" range="-4 4" actuatorfrcrange="-1000 1000" />
        <geom size="0.1 0.125 0.1" type="box" rgba="0.3 0.5 0.7 1" contype="1" conaffinity="0" density="0" group="1" class="visualgeom" />
        <geom type="box" rgba="0.3 0.5 0.7 1" size="0.1 0.125 0.1" />
        
        <body name="pole" pos="0.12 0 0">
          <inertial pos="0 0 0.47" mass="1" diaginertia="0.01 0.01 0.0005" />
          <joint name="cart_to_pole" pos="0 0 0" axis="1 0 0" type="hinge" range="-1.57 1.57" actuatorfrcrange="-1000 1000" />
          <geom size="0.02 0.03 0.5" pos="0 0 0.47" type="box" rgba="0.1 0.1 0.3 1" contype="1" conaffinity="0" density="0" group="1" class="visualgeom" />
          <geom type="box" rgba="0.1 0.0 0.3 1" size="0.02 0.03 0.5" pos="0 0 0.47" />
        </body>
      </body>
    </body>
  </worldbody>

  <asset>
    <texture name="texplane" type="2d" builtin="checker" rgb1=".0 .0 .0" rgb2=".8 .8 .8" width="100" height="100" />
    <material name="matplane" reflectance="0." texture="texplane" texrepeat="1 1" texuniform="true" />
    <material name="visualgeom" rgba="0.5 0.9 0.2 1" />
  </asset>

  <actuator>
    <motor name="slider_to_cart" joint="slider_to_cart" ctrllimited="true" ctrlrange="-1000 1000" gear="1" />
    <motor name="cart_to_pole" joint="cart_to_pole" ctrllimited="true" ctrlrange="-1000 1000" gear="1" />
  </actuator>

  <sensor>
    <actuatorpos name="slider_to_cart_p" actuator="slider_to_cart" />
    <actuatorvel name="slider_to_cart_v" actuator="slider_to_cart" />
    <actuatorfrc name="slider_to_cart_f" actuator="slider_to_cart" noise="0.001" />
    <actuatorpos name="cart_to_pole_p" actuator="cart_to_pole" />
    <actuatorvel name="cart_to_pole_v" actuator="cart_to_pole" />
    <actuatorfrc name="cart_to_pole_f" actuator="cart_to_pole" noise="0.001" />
    <framequat name="orientation" objtype="site" noise="0.001" objname="imu" />
    <gyro name="angular-velocity" site="imu" noise="0.005" cutoff="34.9" />
  </sensor>
</mujoco>
